Workbook
Name Amortization_Years: ASSUMPTIONS!$B$81
Name Annual_Debt_Service: 'DEBT SCHEDULE'!$B$7
Name Avg_Current_Rent: ASSUMPTIONS!$D$27
Name Avg_Market_Rent: ASSUMPTIONS!$E$27
Name CapEx_Per_Unit: ASSUMPTIONS!$B$75
Name Common_Area_Reno: ASSUMPTIONS!$B$65
Name Exit_Cap_Rate: ASSUMPTIONS!$B$90
Name Hold_Period: ASSUMPTIONS!$B$89
Name InPlace_Rent_Growth: ASSUMPTIONS!$B$71
Name Interest_Rate: ASSUMPTIONS!$B$80
Name Levered_IRR: 'ANNUAL CASH FLOW'!$B$49
Name Loan_Amount: ASSUMPTIONS!$B$86
Name LTV: ASSUMPTIONS!$B$79
Name Market_Rent_Growth: ASSUMPTIONS!$B$70
Name Mgmt_Fee_Pct: ASSUMPTIONS!$B$53
Name Monthly_Payment: 'DEBT SCHEDULE'!$B$6
Name OpEx_Growth: ASSUMPTIONS!$B$73
Name Other_Income_Growth: ASSUMPTIONS!$B$72
Name Prop13_Cap: ASSUMPTIONS!$B$95
Name Purchase_Price: ASSUMPTIONS!$B$16
Name Reno_Contingency_Pct: ASSUMPTIONS!$B$66
Name Sale_Costs_Pct: ASSUMPTIONS!$B$91
Name Special_Assessments: ASSUMPTIONS!$B$96
Name Stabilized_Vacancy: ASSUMPTIONS!$B$74
Name T12_EGI: ASSUMPTIONS!$B$42
Name T12_GPR: ASSUMPTIONS!$B$32
Name T12_NOI: ASSUMPTIONS!$B$60
Name T12_OpEx: ASSUMPTIONS!$B$59
Name T12_Other_Income: ASSUMPTIONS!$B$38
Name Tax_Rate: ASSUMPTIONS!$B$94
Name Total_Equity: 'SOURCES & USES'!$B$5
Name Total_Renovation_Budget: ASSUMPTIONS!$B$67
Name Total_Unit_Reno_Cost: ASSUMPTIONS!$F$27
Name Total_Units: ASSUMPTIONS!$B$27
Name Total_Uses: 'SOURCES & USES'!$B$23

Sheet ASSUMPTIONS
A1: AEQUITAS BEDROCK HOUSING - UNDERWRITING ASSUMPTIONS
A3: PROPERTY INFORMATION
A4: Property Name | B4: Deal 3 - 20th Place Sacramento, 1925, F Street, Boulevard Park, Sacramento, Sacramento County, California, 95811, United States
A5: Address | B5: 95814
A6: City | B6: 95814
A7: County | B7: Sacramento County
A8: State | B8: CA
A9: ZIP Code | B9: 95814
A10: Year Built | B10: 1985
A11: Building Type | B11: Garden Style
A12: Number of Buildings | B12: 4
A13: Parking Spaces | B13: 300
A15: ACQUISITION
A16: Purchase Price | B16: 15000000
A17: Acquisition Date | B17: 46021.955
A18: Earnest Money % | B18: 0.02
A19: Closing Costs % | B19: 0.2
A20: Due Diligence Costs | B20: 50000
A22: UNIT MIX
A23: Unit Type | B23: Count | C23: Avg SF | D23: Current Rent | E23: Market Rent | F23: Reno Cost/Unit
A24: 1BR/1BA | B24: 60 | C24: 650 | D24: 2043.4 | E24: 2404 | F24: 8000
A25: 2BR/2BA | B25: 100 | C25: 900 | D25: 2404 | E25: 2764.6 | F25: 10000
A26: 3BR/2BA | B26: 40 | C26: 1100 | D26: 2884.8 | E26: 3365.6 | F26: 12000
A27: TOTALS | B27: =SUM(B24:B26) -> 200 | C27: =SUMPRODUCT(B24:B26,C24:C26)/B27 -> 865 | D27: =SUMPRODUCT(B24:B26,D24:D26)/B27 -> 2391.98 | E27: =SUMPRODUCT(B24:B26,E24:E26)/B27 -> 2776.62 | F27: =SUMPRODUCT(B24:B26,F24:F26) -> 1960000
A29: CURRENT OPERATIONS (T12)
A30: Physical Occupancy % | B30: 0.95
A31: Economic Occupancy % | B31: 0.9
A32: Gross Potential Rent (Annual) | B32: =Total_Units*Avg_Current_Rent*12 -> 5740752
A33: Other Income (Annual):
A34: Laundry ($/unit/month) | B34: 15
A35: Pet Rent ($/unit/month) | B35: 25
A36: Parking ($/space/month) | B36: 30
A37: Other ($/unit/month) | B37: 10
A38: Total Other Income (Annual) | B38: =(B34+B35+B37)*Total_Units*12+B36*300*12 -> 228000
A39: Vacancy Loss (Annual) | B39: 288480
A40: Concessions (Annual) | B40: 20000
A41: Bad Debt (Annual) | B41: 25000
A42: Effective Gross Income (EGI) | B42: =T12_GPR+T12_Other_Income-B39-B40-B41 -> 5635272
A44: OPERATING EXPENSES (T12)
A45: Property Taxes | B45: 165000
...

Sheet SOURCES & USES
A1: SOURCES & USES OF FUNDS
A3: SOURCES
A4: Loan Proceeds | B4: =Loan_Amount -> 11250000
A5: Equity | B5: =B9-B4 -> -11250000
A6: TOTAL SOURCES | B6: =B4+B5 -> 0
A8: USES
A9: Acquisition Costs
A10: Purchase Price | B10: =Purchase_Price -> 15000000
A11: Closing Costs | B11: =Purchase_Price*ASSUMPTIONS!B18 -> 300000
A12: Due Diligence | B12: =ASSUMPTIONS!B19 -> 0.2
A13: Subtotal Acquisition | B13: =SUM(B10:B12) -> 15300000
A15: Renovation Costs
A16: Total Renovation Budget | B16: =Total_Renovation_Budget -> 29656000
A18: Financing Costs
A19: Loan Origination Fee | B19: =Loan_Amount*ASSUMPTIONS!B95 -> 225000
A20: Lender Legal/DD | B20: =ASSUMPTIONS!B96 -> 0
A21: Subtotal Financing | B21: =SUM(B19:B20) -> 225000
A23: TOTAL USES | B23: =B13+B16+B21 -> 45181000
A25: PER UNIT METRICS
A26: Purchase Price per Unit | B26: =Purchase_Price/Total_Units -> 75000
A27: Renovation Cost per Unit | B27: =Total_Renovation_Budget/Total_Units -> 148280
A28: Total Project Cost per Unit | B28: =Total_Uses/Total_Units -> 225905

Sheet DEBT SCHEDULE
A1: DEBT SCHEDULE
A3: Loan Amount: | B3: =Loan_Amount -> 11250000
A4: Interest Rate: | B4: =Interest_Rate -> 0.065
A5: Amortization: | B5: =Amortization_Years -> 30 | C5: years
A6: Monthly Payment: | B6: =-PMT(Interest_Rate/12,Amortization_Years*12,Loan_Amount) -> 71107.653
A7: Annual Debt Service: | B7: =Monthly_Payment*12 -> 853291.83
A10: Year | B10: Month | C10: Beg Balance | D10: Principal | E10: Interest | F10: Total Pmt | G10: End Balance | H10: Cum Principal | I10: Cum Interest
A11: 1 | B11: 1 | C11: =Loan_Amount -> 11250000 | D11: =Monthly_Payment-E11 -> 10170.153 | E11: =C11*Interest_Rate/12 -> 60937.5 | F11: =Monthly_Payment -> 71107.653 | G11: =C11-D11 -> 11239830 | H11: =D11 -> 10170.153 | I11: =E11 -> 60937.5
A12: 1 | B12: 2 | C12: =G11 -> 11239830 | D12: =Monthly_Payment-E12 -> 10225.241 | E12: =C12*Interest_Rate/12 -> 60882.412 | F12: =Monthly_Payment -> 71107.653 | G12: =C12-D12 -> 11229605 | H12: =H11+D12 -> 20395.394 | I12: =I11+E12 -> 121819.91
A13: 1 | B13: 3 | C13: =G12 -> 11229605 | D13: =Monthly_Payment-E13 -> 10280.628 | E13: =C13*Interest_Rate/12 -> 60827.025 | F13: =Monthly_Payment -> 71107.653 | G13: =C13-D13 -> 11219324 | H13: =H12+D13 -> 30676.021 | I13: =I12+E13 -> 182646.94
A14: 1 | B14: 4 | C14: =G13 -> 11219324 | D14: =Monthly_Payment-E14 -> 10336.314 | E14: =C14*Interest_Rate/12 -> 60771.338 | F14: =Monthly_Payment -> 71107.653 | G14: =C14-D14 -> 11208988 | H14: =H13+D14 -> 41012.336 | I14: =I13+E14 -> 243418.27
A15: 1 | B15: 5 | C15: =G14 -> 11208988 | D15: =Monthly_Payment-E15 -> 10392.303 | E15: =C15*Interest_Rate/12 -> 60715.35 | F15: =Monthly_Payment -> 71107.653 | G15: =C15-D15 -> 11198595 | H15: =H14+D15 -> 51404.639 | I15: =I14+E15 -> 304133.62
A16: 1 | B16: 6 | C16: =G15 -> 11198595 | D16: =Monthly_Payment-E16 -> 10448.594 | E16: =C16*Interest_Rate/12 -> 60659.058 | F16: =Monthly_Payment -> 71107.653 | G16: =C16-D16 -> 11188147 | H16: =H15+D16 -> 61853.233 | I16: =I15+E16 -> 364792.68
A17: 1 | B17: 7 | C17: =G16 -> 11188147 | D17: =Monthly_Payment-E17 -> 10505.191 | E17: =C17*Interest_Rate/12 -> 60602.462 | F17: =Monthly_Payment -> 71107.653 | G17: =C17-D17 -> 11177642 | H17: =H16+D17 -> 72358.424 | I17: =I16+E17 -> 425395.14
A18: 1 | B18: 8 | C18: =G17 -> 11177642 | D18: =Monthly_Payment-E18 -> 10562.094 | E18: =C18*Interest_Rate/12 -> 60545.559 | F18: =Monthly_Payment -> 71107.653 | G18: =C18-D18 -> 11167079 | H18: =H17+D18 -> 82920.518 | I18: =I17+E18 -> 485940.7
A19: 1 | B19: 9 | C19: =G18 -> 11167079 | D19: =Monthly_Payment-E19 -> 10619.305 | E19: =C19*Interest_Rate/12 -> 60488.347 | F19: =Monthly_Payment -> 71107.653 | G19: =C19-D19 -> 11156460 | H19: =H18+D19 -> 93539.824 | I19: =I18+E19 -> 546429.05
A20: 1 | B20: 10 | C20: =G19 -> 11156460 | D20: =Monthly_Payment-E20 -> 10676.827 | E20: =C20*Interest_Rate/12 -> 60430.826 | F20: =Monthly_Payment -> 71107.653 | G20: =C20-D20 -> 11145783 | H20: =H19+D20 -> 104216.65 | I20: =I19+E20 -> 606859.88
A21: 1 | B21: 11 | C21: =G20 -> 11145783 | D21: =Monthly_Payment-E21 -> 10734.659 | E21: =C21*Interest_Rate/12 -> 60372.993 | F21: =Monthly_Payment -> 71107.653 | G21: =C21-D21 -> 11135049 | H21: =H20+D21 -> 114951.31 | I21: =I20+E21 -> 667232.87
A22: 1 | B22: 12 | C22: =G21 -> 11135049 | D22: =Monthly_Payment-E22 -> 10792.806 | E22: =C22*Interest_Rate/12 -> 60314.847 | F22: =Monthly_Payment -> 71107.653 | G22: =C22-D22 -> 11124256 | H22: =H21+D22 -> 125744.12 | I22: =I21+E22 -> 727547.72
A23: 2 | B23: 1 | C23: =G22 -> 11124256 | D23: =Monthly_Payment-E23 -> 10851.267 | E23: =C23*Interest_Rate/12 -> 60256.386 | F23: =Monthly_Payment -> 71107.653 | G23: =C23-D23 -> 11113405 | H23: =H22+D23 -> 136595.38 | I23: =I22+E23 -> 787804.1
... A370: 30 | B370: 12 | C370: =G369 -> 70724.561 | D370: =Monthly_Payment-E370 -> 70724.561 | E370: =C370*Interest_Rate/12 -> 383.09137 | F370: =Monthly_Payment -> 71107.653 | G370: =C370-D370 -> -6.2791514e-08 | H370: =H369+D370 -> 11250000 | I370: =I369+E370 -> 14348755

Sheet ANNUAL CASH FLOW
A1: ANNUAL CASH FLOW PRO FORMA (10 Years)
A3: Year | B3: 0 | C3: 1 | D3: 2 | E3: 3 | F3: 4 | G3: 5 | H3: 6 | I3: 7 | J3: 8 | K3: 9 | L3: 10
A4: REVENUE
A5: Gross Potential Rent | B5: =T12_GPR -> 5740752 | C5: =T12_GPR*POWER(1+InPlace_Rent_Growth,1)*(1-0.4)+Total_Units*Avg_Market_Rent*12*POWER(1+Market_Rent_Growth,1)*0.4 -> 6276084.3 | D5: =T12_GPR*POWER(1+InPlace_Rent_Growth,2)*(1-0.8)+Total_Units*Avg_Market_Rent*12*POWER(1+Market_Rent_Growth,2)*0.8 -> 6862050.5 | E5: =Total_Units*Avg_Market_Rent*12*POWER(1+Market_Rent_Growth,3) -> 7281810.3 | F5: =Total_Units*Avg_Market_Rent*12*POWER(1+Market_Rent_Growth,4) -> 7500264.7 | G5: =Total_Units*Avg_Market_Rent*12*POWER(1+Market_Rent_Growth,5) -> 7725272.6 | H5: =Total_Units*Avg_Market_Rent*12*POWER(1+Market_Rent_Growth,6) -> 7957030.8 | I5: =Total_Units*Avg_Market_Rent*12*POWER(1+Market_Rent_Growth,7) -> 8195741.7 | J5: =Total_Units*Avg_Market_Rent*12*POWER(1+Market_Rent_Growth,8) -> 8441613.9 | K5: =Total_Units*Avg_Market_Rent*12*POWER(1+Market_Rent_Growth,9) -> 8694862.4 | L5: =Total_Units*Avg_Market_Rent*12*POWER(1+Market_Rent_Growth,10) -> 8955708.2
A6: Other Income | B6: =T12_Other_Income -> 228000 | C6: =T12_Other_Income*POWER(1+Other_Income_Growth,1) -> 234840 | D6: =T12_Other_Income*POWER(1+Other_Income_Growth,2) -> 241885.2 | E6: =T12_Other_Income*POWER(1+Other_Income_Growth,3) -> 249141.76 | F6: =T12_Other_Income*POWER(1+Other_Income_Growth,4) -> 256616.01 | G6: =T12_Other_Income*POWER(1+Other_Income_Growth,5) -> 264314.49 | H6: =T12_Other_Income*POWER(1+Other_Income_Growth,6) -> 272243.92 | I6: =T12_Other_Income*POWER(1+Other_Income_Growth,7) -> 280411.24 | J6: =T12_Other_Income*POWER(1+Other_Income_Growth,8) -> 288823.58 | K6: =T12_Other_Income*POWER(1+Other_Income_Growth,9) -> 297488.29 | L6: =T12_Other_Income*POWER(1+Other_Income_Growth,10) -> 306412.93
A7: Gross Potential Income | B7: =B5+B6 -> 5968752 | C7: =C5+C6 -> 6510924.3 | D7: =D5+D6 -> 7103935.7 | E7: =E5+E6 -> 7530952.1 | F7: =F5+F6 -> 7756880.7 | G7: =G5+G6 -> 7989587.1 | H7: =H5+H6 -> 8229274.7 | I7: =I5+I6 -> 8476152.9 | ... L7: =L5+L6 -> 9262121.2
A8: Less: Economic Loss
A9: Vacancy & Credit Loss | B9: =B7*0.14 -> 835625.28 | C9: =C7*0.12 -> 781310.92 | D9: =D7*0.1 -> 710393.57 | E9: =E7*Stabilized_Vacancy -> 376547.6 | F9: =F7*Stabilized_Vacancy -> 387844.03 | G9: =G7*Stabilized_Vacancy -> 399479.35 | H9: =H7*Stabilized_Vacancy -> 411463.73 | I9: =I7*Stabilized_Vacancy -> 423807.65 | J9: =J7*Stabilized_Vacancy -> 436521.88 | K9: =K7*Stabilized_Vacancy -> 449617.53 | L9: =L7*Stabilized_Vacancy -> 463106.06
A10: Effective Gross Income (EGI) | B10: =B7-B9 -> 5133126.7 | C10: =C7-C9 -> 5729613.4 | D10: =D7-D9 -> 6393542.2 | E10: =E7-E9 -> 7154404.5 | F10: =F7-F9 -> 7369036.6 | G10: =G7-G9 -> 7590107.7 | H10: =H7-H9 -> 7817811 | I10: =I7-I9 -> 8052345.3 | ... L10: =L7-L9 -> 8799015.1
A12: OPERATING EXPENSES
A13: Property Taxes | B13: =Purchase_Price*Tax_Rate+Special_Assessments -> 165000 | C13: =Purchase_Price*POWER(1+Prop13_Cap,1)*Tax_Rate+Special_Assessments -> 168300 | D13: =Purchase_Price*POWER(1+Prop13_Cap,2)*Tax_Rate+Special_Assessments -> 171666 | E13: =Purchase_Price*POWER(1+Prop13_Cap,3)*Tax_Rate+Special_Assessments -> 175099.32 | F13: =Purchase_Price*POWER(1+Prop13_Cap,4)*Tax_Rate+Special_Assessments -> 178601.31 | G13: =Purchase_Price*POWER(1+Prop13_Cap,5)*Tax_Rate+Special_Assessments -> 182173.33 | H13: =Purchase_Price*POWER(1+Prop13_Cap,6)*Tax_Rate+Special_Assessments -> 185816.8 | I13: =Purchase_Price*POWER(1+Prop13_Cap,7)*Tax_Rate+Special_Assessments -> 189533.14 | J13: =Purchase_Price*POWER(1+Prop13_Cap,8)*Tax_Rate+Special_Assessments -> 193323.8 | K13: =Purchase_Price*POWER(1+Prop13_Cap,9)*Tax_Rate+Special_Assessments -> 197190.27 | L13: =Purchase_Price*POWER(1+Prop13_Cap,10)*Tax_Rate+Special_Assessments -> 201134.08
A14: Insurance | B14: =ASSUMPTIONS!B58 -> 0 | C14: =ASSUMPTIONS!B58*POWER(1+OpEx_Growth,1) -> 0 | D14: =ASSUMPTIONS!B58*POWER(1+OpEx_Growth,2) -> 0 | E14: =ASSUMPTIONS!B58*POWER(1+OpEx_Growth,3) -> 0 | F14: =ASSUMPTIONS!B58*POWER(1+OpEx_Growth,4) -> 0 | G14: =ASSUMPTIONS!B58*POWER(1+OpEx_Growth,5) -> 0 | H14: =ASSUMPTIONS!B58*POWER(1+OpEx_Growth,6) -> 0 | I14: =ASSUMPTIONS!B58*POWER(1+OpEx_Growth,7) -> 0 | J14: =ASSUMPTIONS!B58*POWER(1+OpEx_Growth,8) -> 0 | K14: =ASSUMPTIONS!B58*POWER(1+OpEx_Growth,9) -> 0 | L14: =ASSUMPTIONS!B58*POWER(1+OpEx_Growth,10) -> 0
A15: Utilities | B15: =ASSUMPTIONS!B59+ASSUMPTIONS!B60+ASSUMPTIONS!B61+ASSUMPTIONS!B62 -> 5635272.2 | C15: =ASSUMPTIONS!B59+ASSUMPTIONS!B60+ASSUMPTIONS!B61+ASSUMPTIONS!B62*POWER(1+OpEx_Growth,1) -> 5635272.2 | D15: =ASSUMPTIONS!B59+ASSUMPTIONS!B60+ASSUMPTIONS!B61+ASSUMPTIONS!B62*POWER(1+OpEx_Growth,2) -> 5635272.2 | E15: =ASSUMPTIONS!B59+ASSUMPTIONS!B60+ASSUMPTIONS!B61+ASSUMPTIONS!B62*POWER(1+OpEx_Growth,3) -> 5635272.2 | F15: =ASSUMPTIONS!B59+ASSUMPTIONS!B60+ASSUMPTIONS!B61+ASSUMPTIONS!B62*POWER(1+OpEx_Growth,4) -> 5635272.2 | G15: =ASSUMPTIONS!B59+ASSUMPTIONS!B60+ASSUMPTIONS!B61+ASSUMPTIONS!B62*POWER(1+OpEx_Growth,5) -> 5635272.2 | H15: =ASSUMPTIONS!B59+ASSUMPTIONS!B60+ASSUMPTIONS!B61+ASSUMPTIONS!B62*POWER(1+OpEx_Growth,6) -> 5635272.2 | I15: =ASSUMPTIONS!B59+ASSUMPTIONS!B60+ASSUMPTIONS!B61+ASSUMPTIONS!B62*POWER(1+OpEx_Growth,7) -> 5635272.2 | J15: =ASSUMPTIONS!B59+ASSUMPTIONS!B60+ASSUMPTIONS!B61+ASSUMPTIONS!B62*POWER(1+OpEx_Growth,8) -> 5635272.2 | K15: =ASSUMPTIONS!B59+ASSUMPTIONS!B60+ASSUMPTIONS!B61+ASSUMPTIONS!B62*POWER(1+OpEx_Growth,9) -> 5635272.2 | L15: =ASSUMPTIONS!B59+ASSUMPTIONS!B60+ASSUMPTIONS!B61+ASSUMPTIONS!B62*POWER(1+OpEx_Growth,10) -> 5635272.2
A16: Repairs & Maintenance | B16: =ASSUMPTIONS!B63 -> 0 | C16: =ASSUMPTIONS!B63*POWER(1+OpEx_Growth,1) -> 0 | D16: =ASSUMPTIONS!B63*POWER(1+OpEx_Growth,2) -> 0 | E16: =ASSUMPTIONS!B63*POWER(1+OpEx_Growth,3) -> 0 | F16: =ASSUMPTIONS!B63*POWER(1+OpEx_Growth,4) -> 0 | G16: =ASSUMPTIONS!B63*POWER(1+OpEx_Growth,5) -> 0 | H16: =ASSUMPTIONS!B63*POWER(1+OpEx_Growth,6) -> 0 | I16: =ASSUMPTIONS!B63*POWER(1+OpEx_Growth,7) -> 0 | J16: =ASSUMPTIONS!B63*POWER(1+OpEx_Growth,8) -> 0 | K16: =ASSUMPTIONS!B63*POWER(1+OpEx_Growth,9) -> 0 | L16: =ASSUMPTIONS!B63*POWER(1+OpEx_Growth,10) -> 0
A17: Payroll | B17: =ASSUMPTIONS!B64 -> 1960000 | C17: =ASSUMPTIONS!B64*POWER(1+OpEx_Growth,1) -> 2018800 | D17: =ASSUMPTIONS!B64*POWER(1+OpEx_Growth,2) -> 2079364 | E17: =ASSUMPTIONS!B64*POWER(1+OpEx_Growth,3) -> 2141744.9 | F17: =ASSUMPTIONS!B64*POWER(1+OpEx_Growth,4) -> 2205997.3 | G17: =ASSUMPTIONS!B64*POWER(1+OpEx_Growth,5) -> 2272177.2 | H17: =ASSUMPTIONS!B64*POWER(1+OpEx_Growth,6) -> 2340342.5 | I17: =ASSUMPTIONS!B64*POWER(1+OpEx_Growth,7) -> 2410552.8 | J17: =ASSUMPTIONS!B64*POWER(1+OpEx_Growth,8) -> 2482869.4 | K17: =ASSUMPTIONS!B64*POWER(1+OpEx_Growth,9) -> 2557355.4 | L17: =ASSUMPTIONS!B64*POWER(1+OpEx_Growth,10) -> 2634076.1
A18: Marketing | B18: =ASSUMPTIONS!B68 -> 0 | C18: =ASSUMPTIONS!B68*POWER(1+OpEx_Growth,1) -> 0 | D18: =ASSUMPTIONS!B68*POWER(1+OpEx_Growth,2) -> 0 | E18: =ASSUMPTIONS!B68*POWER(1+OpEx_Growth,3) -> 0 | F18: =ASSUMPTIONS!B68*POWER(1+OpEx_Growth,4) -> 0 | G18: =ASSUMPTIONS!B68*POWER(1+OpEx_Growth,5) -> 0 | H18: =ASSUMPTIONS!B68*POWER(1+OpEx_Growth,6) -> 0 | I18: =ASSUMPTIONS!B68*POWER(1+OpEx_Growth,7) -> 0 | J18: =ASSUMPTIONS!B68*POWER(1+OpEx_Growth,8) -> 0 | K18: =ASSUMPTIONS!B68*POWER(1+OpEx_Growth,9) -> 0 | L18: =ASSUMPTIONS!B68*POWER(1+OpEx_Growth,10) -> 0
A19: Legal/Professional | B19: =ASSUMPTIONS!B69 -> 0 | C19: =ASSUMPTIONS!B69*POWER(1+OpEx_Growth,1) -> 0 | D19: =ASSUMPTIONS!B69*POWER(1+OpEx_Growth,2) -> 0 | E19: =ASSUMPTIONS!B69*POWER(1+OpEx_Growth,3) -> 0 | F19: =ASSUMPTIONS!B69*POWER(1+OpEx_Growth,4) -> 0 | G19: =ASSUMPTIONS!B69*POWER(1+OpEx_Growth,5) -> 0 | H19: =ASSUMPTIONS!B69*POWER(1+OpEx_Growth,6) -> 0 | I19: =ASSUMPTIONS!B69*POWER(1+OpEx_Growth,7) -> 0 | J19: =ASSUMPTIONS!B69*POWER(1+OpEx_Growth,8) -> 0 | K19: =ASSUMPTIONS!B69*POWER(1+OpEx_Growth,9) -> 0 | L19: =ASSUMPTIONS!B69*POWER(1+OpEx_Growth,10) -> 0
A20: Administrative | B20: =ASSUMPTIONS!B70 -> 0.03 | C20: =ASSUMPTIONS!B70*POWER(1+OpEx_Growth,1) -> 0.0309 | D20: =ASSUMPTIONS!B70*POWER(1+OpEx_Growth,2) -> 0.031827 | E20: =ASSUMPTIONS!B70*POWER(1+OpEx_Growth,3) -> 0.03278181 | F20: =ASSUMPTIONS!B70*POWER(1+OpEx_Growth,4) -> 0.033765264 | G20: =ASSUMPTIONS!B70*POWER(1+OpEx_Growth,5) -> 0.034778222 | H20: =ASSUMPTIONS!B70*POWER(1+OpEx_Growth,6) -> 0.035821569 | I20: =ASSUMPTIONS!B70*POWER(1+OpEx_Growth,7) -> 0.036896216 | J20: =ASSUMPTIONS!B70*POWER(1+OpEx_Growth,8) -> 0.038003102 | K20: =ASSUMPTIONS!B70*POWER(1+OpEx_Growth,9) -> 0.039143196 | L20: =ASSUMPTIONS!B70*POWER(1+OpEx_Growth,10) -> 0.040317491
A21: Management Fee | B21: =B10*Mgmt_Fee_Pct -> 205325.07 | C21: =C10*Mgmt_Fee_Pct -> 229184.54 | D21: =D10*Mgmt_Fee_Pct -> 255741.69 | E21: =E10*Mgmt_Fee_Pct -> 286176.18 | F21: =F10*Mgmt_Fee_Pct -> 294761.47 | G21: =G10*Mgmt_Fee_Pct -> 303604.31 | H21: =H10*Mgmt_Fee_Pct -> 312712.44 | I21: =I10*Mgmt_Fee_Pct -> 322093.81 | ... L21: =L10*Mgmt_Fee_Pct -> 351960.6
A22: Total Operating Expenses | B22: =SUM(B13:B21) -> 7965597.3 | C22: =SUM(C13:C21) -> 8051556.8 | D22: =SUM(D13:D21) -> 8142043.9 | E22: =SUM(E13:E21) -> 8238292.6 | F22: =SUM(F13:F21) -> 8314632.3 | G22: =SUM(G13:G21) -> 8393227.1 | H22: =SUM(H13:H21) -> 8474144 | I22: =SUM(I13:I21) -> 8557452 | ... L22: =SUM(L13:L21) -> 8822443
A24: NET OPERATING INCOME (NOI) | B24: =B10-B22 -> -2832470.6 | C24: =C10-C22 -> -2321943.3 | D24: =D10-D22 -> -1748501.8 | E24: =E10-E22 -> -1083888.2 | F24: =F10-F22 -> -945595.64 | G24: =G10-G22 -> -803119.33 | H24: =H10-H22 -> -656333.01 | I24: =I10-I22 -> -505106.67 | ... L24: =L10-L22 -> -23427.914
A25: NOI per Unit | B25: =B24/Total_Units -> -14162.353 | C25: =C24/Total_Units -> -11609.717 | D25: =D24/Total_Units -> -8742.5088 | E25: =E24/Total_Units -> -5419.4408 | F25: =F24/Total_Units -> -4727.9782 | G25: =G24/Total_Units -> -4015.5967 | H25: =H24/Total_Units -> -3281.6651 | I25: =I24/Total_Units -> -2525.5333 | ... L25: =L24/Total_Units -> -117.13957
A26: NOI Margin % | B26: =B24/B10 -> -0.55180219 | C26: =C24/C10 -> -0.40525306 | D26: =D24/D10 -> -0.27347935 | E26: =E24/E10 -> -0.15149942 | F26: =F24/F10 -> -0.12832012 | G26: =G24/G10 -> -0.10581132 | H26: =H24/H10 -> -0.083953554 | I26: =I24/I10 -> -0.062727895 | ... L26: =L24/L10 -> -0.0026625609
A28: CAPITAL EXPENDITURES & DEBT SERVICE
A29: CapEx Reserve | B29: =Total_Units*CapEx_Per_Unit -> 80000 | C29: =Total_Units*CapEx_Per_Unit -> 80000 | D29: =Total_Units*CapEx_Per_Unit -> 80000 | E29: =Total_Units*CapEx_Per_Unit -> 80000 | F29: =Total_Units*CapEx_Per_Unit -> 80000 | G29: =Total_Units*CapEx_Per_Unit -> 80000 | H29: =Total_Units*CapEx_Per_Unit -> 80000 | I29: =Total_Units*CapEx_Per_Unit -> 80000 | ... L29: =Total_Units*CapEx_Per_Unit -> 80000
A30: Renovation Expenditures | B30: =Total_Renovation_Budget*0.4 -> 11862400 | C30: =Total_Renovation_Budget*0.4 -> 11862400 | D30: =Total_Renovation_Budget*0.2 -> 5931200 | E30: 0 | F30: 0 | G30: 0 | H30: 0 | I30: 0 | J30: 0 | K30: 0 | L30: 0
A31: Annual Debt Service | B31: 0 | C31: =Annual_Debt_Service -> 853291.83 | D31: =Annual_Debt_Service -> 853291.83 | E31: =Annual_Debt_Service -> 853291.83 | F31: =Annual_Debt_Service -> 853291.83 | G31: =Annual_Debt_Service -> 853291.83 | H31: =Annual_Debt_Service -> 853291.83 | I31: =Annual_Debt_Service -> 853291.83 | J31: =Annual_Debt_Service -> 853291.83 | ... L31: =Annual_Debt_Service -> 853291.83
A32: Debt Service Coverage Ratio | B32: N/A | C32: =C24/C31 -> -2.7211597 | D32: =D24/D31 -> -2.0491251 | E32: =E24/E31 -> -1.2702432 | F32: =F24/F31 -> -1.1081738 | G32: =G24/G31 -> -0.94120124 | H32: =H24/H31 -> -0.76917766 | I32: =I24/I31 -> -0.59195067 | J32: =J24/J31 -> -0.40936331 | ... L32: =L24/L31 -> -0.027455922
A34: NET CASH FLOW (Before Sale) | B34: =B24-B29-B30-B31 -> -14774871 | C34: =C24-C29-C30-C31 -> -15117635 | D34: =D24-D29-D30-D31 -> -8612993.6 | E34: =E24-E29-E30-E31 -> -2017180 | F34: =F24-F29-F30-F31 -> -1878887.5 | G34: =G24-G29-G30-G31 -> -1736411.2 | H34: =H24-H29-H30-H31 -> -1589624.8 | I34: =I24-I29-I30-I31 -> -1438398.5 | ... L34: =L24-L29-L30-L31 -> -956719.75
A36: SALE PROCEEDS (at exit)
A37: Forward NOI (Year N+1) | B37: =C24 -> -2321943.3 | C37: =D24 -> -1748501.8 | D37: =E24 -> -1083888.2 | E37: =F24 -> -945595.64 | F37: =G24 -> -803119.33 | G37: =H24 -> -656333.01 | H37: =I24 -> -505106.67 | I37: =J24 -> -349306.37 | ... K37: =L24 -> -23427.914 | L37: =L24*1.03 -> -24130.751
A38: Gross Sale Price (at Exit Cap) | B38: =B37/Exit_Cap_Rate -> -38699056 | C38: =C37/Exit_Cap_Rate -> -29141696 | D38: =D37/Exit_Cap_Rate -> -18064803 | E38: =E37/Exit_Cap_Rate -> -15759927 | F38: =F37/Exit_Cap_Rate -> -13385322 | G38: =G37/Exit_Cap_Rate -> -10938884 | H38: =H37/Exit_Cap_Rate -> -8418444.5 | I38: =I37/Exit_Cap_Rate -> -5821772.8 | ... L38: =L37/Exit_Cap_Rate -> -402179.19
A39: Less: Sale Costs | B39: =B38*Sale_Costs_Pct -> -1547962.2 | C39: =C38*Sale_Costs_Pct -> -1165667.8 | D39: =D38*Sale_Costs_Pct -> -722592.1 | E39: =E38*Sale_Costs_Pct -> -630397.09 | F39: =F38*Sale_Costs_Pct -> -535412.89 | G39: =G38*Sale_Costs_Pct -> -437555.34 | H39: =H38*Sale_Costs_Pct -> -336737.78 | I39: =I38*Sale_Costs_Pct -> -232870.91 | ... L39: =L38*Sale_Costs_Pct -> -16087.168
A40: Net Sale Proceeds (before debt) | B40: =B38-B39 -> -37151094 | C40: =C38-C39 -> -27976028 | D40: =D38-D39 -> -17342210 | E40: =E38-E39 -> -15129530 | F40: =F38-F39 -> -12849909 | G40: =G38-G39 -> -10501328 | H40: =H38-H39 -> -8081706.7 | I40: =I38-I39 -> -5588901.9 | ... L40: =L38-L39 -> -386092.02
A41: Less: Loan Payoff | B41: =Loan_Amount -> 11250000
A42: Net Proceeds to Equity | B42: =B40-B41 -> -48401094 | C42: =C40-C41 -> -27976028 | D42: =D40-D41 -> -17342210 | E42: =E40-E41 -> -15129530 | F42: =F40-F41 -> -12849909 | G42: =G40-G41 -> -10501328 | H42: =H40-H41 -> -8081706.7 | I42: =I40-I41 -> -5588901.9 | ... L42: =L40-L41 -> -386092.02
A44: TOTAL CASH FLOW TO EQUITY | B44: =-Total_Equity+B34 -> -3524870.6 | C44: =IF(1=Hold_Period,C34+C42,C34) -> -15117635 | D44: =IF(2=Hold_Period,D34+D42,D34) -> -8612993.6 | E44: =IF(3=Hold_Period,E34+E42,E34) -> -2017180 | F44: =IF(4=Hold_Period,F34+F42,F34) -> -1878887.5 | G44: =IF(5=Hold_Period,G34+G42,G34) -> -1736411.2 | H44: =IF(6=Hold_Period,H34+H42,H34) -> -1589624.8 | I44: =IF(7=Hold_Period,I34+I42,I34) -> -1438398.5 | J44: =IF(8=Hold_Period,J34+J42,J34) -> -1282598.2 | K44: =IF(9=Hold_Period,K34+K42,K34) -> -1122086 | L44: =IF(10=Hold_Period,L34+L42,L34) -> -1342811.8
A47: RETURN METRICS
A48: Total Equity Invested | B48: =Total_Equity -> -11250000
A49: Levered IRR | B49: =IRR(B44:L44) -> #NUM!
...

Sheet REFERENCE DATA
A1: REFERENCE DATA
A3: This tab contains lookup data and reference tables
A5: Unit Types
A6: Studio
A7: 1BR/1BA
A8: 2BR/1BA
A9: 2BR/2BA
A10: 3BR/2BA
A11: 3BR/2.5BA
A13: Loan Types
A14: Agency Fixed
A15: Bridge Floating
A16: Bridge to Agency
